Workbook

Sheet Start Here
A1: Lab 4: Reconcile Accounts and Explain Variances
A3: Course | B3: Generative AI for Finance and Fintech (TGS-2026065050)
A4: TSC mapping | B4: K1 · A2
A5: Objective | B5: Apply deterministic matching and Finance Agent-style variance analysis to a month-end close.
A6: Scenario | B6: The controller must reconcile ERP and bank/ledger extracts and explain material monthly movements.
A7: Expected output | B7: A reconciliation report, exception queue and evidence-backed variance narrative.
A8: Data notice | B8: All names, accounts, transactions and scores are synthetic. Do not replace them with live personal or customer data.
A9: Acceptance | B9: Matched plus exception values reconcile to each source; all unresolved items have a reason and owner; the narrative cites actual values and materiality thresholds.

Sheet Ledger
A1: Reference | B1: Date | C1: Amount SGD | D1: Customer
A2: RCPT-0001 | B2: 46188 | C2: 4238.9 | D2: CUST-022
A3: RCPT-0002 | B3: 46193 | C3: 2854.52 | D3: CUST-006
A4: RCPT-0003 | B4: 46178 | C4: 3462.45 | D4: CUST-033
A5: RCPT-0004 | B5: 46185 | C5: 4293.22 | D5: CUST-030
A6: RCPT-0005 | B6: 46183 | C6: 11581.1 | D6: CUST-006
A7: RCPT-0006 | B7: 46191 | C7: 9628.99 | D7: CUST-010
A8: RCPT-0007 | B8: 46191 | C8: 3096.65 | D8: CUST-018
A9: RCPT-0008 | B9: 46177 | C9: 18972.37 | D9: CUST-023
A10: RCPT-0009 | B10: 46195 | C10: 7328.9 | D10: CUST-004
A11: RCPT-0010 | B11: 46203 | C11: 24166.3 | D11: CUST-004
A12: RCPT-0011 | B12: 46193 | C12: 3505.93 | D12: CUST-029
A13: RCPT-0012 | B13: 46192 | C13: 6203.25 | D13: CUST-019
... A91: RCPT-0090 | B91: 46192 | C91: 21161.17 | D91: CUST-043

Sheet Bank
A1: Reference | B1: Date | C1: Amount SGD | D1: Customer
A2: RCPT-0001 | B2: 46188 | C2: 4238.9 | D2: CUST-022
A3: RCPT-0002 | B3: 46193 | C3: 2854.52 | D3: CUST-006
A4: RCPT-0003 | B4: 46178 | C4: 3462.45 | D4: CUST-033
A5: RCPT-0004 | B5: 46186 | C5: 4293.22 | D5: CUST-030
A6: RCPT-0005 | B6: 46183 | C6: 11581.1 | D6: CUST-006
A7: RCPT-0006 | B7: 46191 | C7: 9628.99 | D7: CUST-010
A8: RCPT-0007 | B8: 46191 | C8: 3096.65 | D8: CUST-018
A9: RCPT-0009 | B9: 46196 | C9: 7328.9 | D9: CUST-004
A10: RCPT-0010 | B10: 46203 | C10: 24166.3 | D10: CUST-004
A11: RCPT-0011 | B11: 46193 | C11: 3505.93 | D11: CUST-029
A12: RCPT-0012 | B12: 46193 | C12: 6203.25 | D12: CUST-019
A13: RCPT-0013 | B13: 46203 | C13: 10652.47 | D13: CUST-035
... A88: BANK-ONLY-01 | B88: 46203 | C88: 8750 | D88: CUST-999

Sheet Reconciliation
A1: Reference | B1: Ledger Date | C1: Ledger Amount | D1: Bank Amount | E1: Difference | F1: Match Status | G1: Owner
A2: RCPT-0001 | B2: 46188 | C2: 4238.9 | D2: {=IFERROR(_xlfn.XLOOKUP(A2,Bank!$A:$A,Bank!$C:$C),0)} -> 4238.9 | E2: =C2-D2 -> 0 | F2: =IF(D2=0,"Missing in bank",IF(ABS(E2)<0.001,"Exact",IF(ABS(E2)<=0.1,"Tolerance","Exception"))) -> Exact
A3: RCPT-0002 | B3: 46193 | C3: 2854.52 | D3: {=IFERROR(_xlfn.XLOOKUP(A3,Bank!$A:$A,Bank!$C:$C),0)} -> 2854.52 | E3: =C3-D3 -> 0 | F3: =IF(D3=0,"Missing in bank",IF(ABS(E3)<0.001,"Exact",IF(ABS(E3)<=0.1,"Tolerance","Exception"))) -> Exact
A4: RCPT-0003 | B4: 46178 | C4: 3462.45 | D4: {=IFERROR(_xlfn.XLOOKUP(A4,Bank!$A:$A,Bank!$C:$C),0)} -> 3462.45 | E4: =C4-D4 -> 0 | F4: =IF(D4=0,"Missing in bank",IF(ABS(E4)<0.001,"Exact",IF(ABS(E4)<=0.1,"Tolerance","Exception"))) -> Exact
A5: RCPT-0004 | B5: 46185 | C5: 4293.22 | D5: {=IFERROR(_xlfn.XLOOKUP(A5,Bank!$A:$A,Bank!$C:$C),0)} -> 4293.22 | E5: =C5-D5 -> 0 | F5: =IF(D5=0,"Missing in bank",IF(ABS(E5)<0.001,"Exact",IF(ABS(E5)<=0.1,"Tolerance","Exception"))) -> Exact
A6: RCPT-0005 | B6: 46183 | C6: 11581.1 | D6: {=IFERROR(_xlfn.XLOOKUP(A6,Bank!$A:$A,Bank!$C:$C),0)} -> 11581.1 | E6: =C6-D6 -> 0 | F6: =IF(D6=0,"Missing in bank",IF(ABS(E6)<0.001,"Exact",IF(ABS(E6)<=0.1,"Tolerance","Exception"))) -> Exact
A7: RCPT-0006 | B7: 46191 | C7: 9628.99 | D7: {=IFERROR(_xlfn.XLOOKUP(A7,Bank!$A:$A,Bank!$C:$C),0)} -> 9628.99 | E7: =C7-D7 -> 0 | F7: =IF(D7=0,"Missing in bank",IF(ABS(E7)<0.001,"Exact",IF(ABS(E7)<=0.1,"Tolerance","Exception"))) -> Exact
A8: RCPT-0007 | B8: 46191 | C8: 3096.65 | D8: {=IFERROR(_xlfn.XLOOKUP(A8,Bank!$A:$A,Bank!$C:$C),0)} -> 3096.65 | E8: =C8-D8 -> 0 | F8: =IF(D8=0,"Missing in bank",IF(ABS(E8)<0.001,"Exact",IF(ABS(E8)<=0.1,"Tolerance","Exception"))) -> Exact
A9: RCPT-0008 | B9: 46177 | C9: 18972.37 | D9: {=IFERROR(_xlfn.XLOOKUP(A9,Bank!$A:$A,Bank!$C:$C),0)} -> 0 | E9: =C9-D9 -> 18972.37 | F9: =IF(D9=0,"Missing in bank",IF(ABS(E9)<0.001,"Exact",IF(ABS(E9)<=0.1,"Tolerance","Exception"))) -> Missing in bank | G9: AR Analyst
A10: RCPT-0009 | B10: 46195 | C10: 7328.9 | D10: {=IFERROR(_xlfn.XLOOKUP(A10,Bank!$A:$A,Bank!$C:$C),0)} -> 7328.9 | E10: =C10-D10 -> 0 | F10: =IF(D10=0,"Missing in bank",IF(ABS(E10)<0.001,"Exact",IF(ABS(E10)<=0.1,"Tolerance","Exception"))) -> Exact
A11: RCPT-0010 | B11: 46203 | C11: 24166.3 | D11: {=IFERROR(_xlfn.XLOOKUP(A11,Bank!$A:$A,Bank!$C:$C),0)} -> 24166.3 | E11: =C11-D11 -> 0 | F11: =IF(D11=0,"Missing in bank",IF(ABS(E11)<0.001,"Exact",IF(ABS(E11)<=0.1,"Tolerance","Exception"))) -> Exact
A12: RCPT-0011 | B12: 46193 | C12: 3505.93 | D12: {=IFERROR(_xlfn.XLOOKUP(A12,Bank!$A:$A,Bank!$C:$C),0)} -> 3505.93 | E12: =C12-D12 -> 0 | F12: =IF(D12=0,"Missing in bank",IF(ABS(E12)<0.001,"Exact",IF(ABS(E12)<=0.1,"Tolerance","Exception"))) -> Exact
A13: RCPT-0012 | B13: 46192 | C13: 6203.25 | D13: {=IFERROR(_xlfn.XLOOKUP(A13,Bank!$A:$A,Bank!$C:$C),0)} -> 6203.25 | E13: =C13-D13 -> 0 | F13: =IF(D13=0,"Missing in bank",IF(ABS(E13)<0.001,"Exact",IF(ABS(E13)<=0.1,"Tolerance","Exception"))) -> Exact
A14: RCPT-0013 | B14: 46202 | C14: 10652.47 | D14: {=IFERROR(_xlfn.XLOOKUP(A14,Bank!$A:$A,Bank!$C:$C),0)} -> 10652.47 | E14: =C14-D14 -> 0 | F14: =IF(D14=0,"Missing in bank",IF(ABS(E14)<0.001,"Exact",IF(ABS(E14)<=0.1,"Tolerance","Exception"))) -> Exact
A15: RCPT-0014 | B15: 46199 | C15: 20002.74 | D15: {=IFERROR(_xlfn.XLOOKUP(A15,Bank!$A:$A,Bank!$C:$C),0)} -> 20002.74 | E15: =C15-D15 -> 0 | F15: =IF(D15=0,"Missing in bank",IF(ABS(E15)<0.001,"Exact",IF(ABS(E15)<=0.1,"Tolerance","Exception"))) -> Exact
A16: RCPT-0015 | B16: 46177 | C16: 18843.68 | D16: {=IFERROR(_xlfn.XLOOKUP(A16,Bank!$A:$A,Bank!$C:$C),0)} -> 18843.68 | E16: =C16-D16 -> 0 | F16: =IF(D16=0,"Missing in bank",IF(ABS(E16)<0.001,"Exact",IF(ABS(E16)<=0.1,"Tolerance","Exception"))) -> Exact
A17: RCPT-0016 | B17: 46194 | C17: 23668.25 | D17: {=IFERROR(_xlfn.XLOOKUP(A17,Bank!$A:$A,Bank!$C:$C),0)} -> 23668.17 | E17: =C17-D17 -> 0.08 | F17: =IF(D17=0,"Missing in bank",IF(ABS(E17)<0.001,"Exact",IF(ABS(E17)<=0.1,"Tolerance","Exception"))) -> Tolerance | G17: AR Analyst
A18: RCPT-0017 | B18: 46179 | C18: 19776.42 | D18: {=IFERROR(_xlfn.XLOOKUP(A18,Bank!$A:$A,Bank!$C:$C),0)} -> 19776.42 | E18: =C18-D18 -> 0 | F18: =IF(D18=0,"Missing in bank",IF(ABS(E18)<0.001,"Exact",IF(ABS(E18)<=0.1,"Tolerance","Exception"))) -> Exact
A19: RCPT-0018 | B19: 46184 | C19: 3027.58 | D19: {=IFERROR(_xlfn.XLOOKUP(A19,Bank!$A:$A,Bank!$C:$C),0)} -> 3027.58 | E19: =C19-D19 -> 0 | F19: =IF(D19=0,"Missing in bank",IF(ABS(E19)<0.001,"Exact",IF(ABS(E19)<=0.1,"Tolerance","Exception"))) -> Exact
A20: RCPT-0019 | B20: 46192 | C20: 16426.24 | D20: {=IFERROR(_xlfn.XLOOKUP(A20,Bank!$A:$A,Bank!$C:$C),0)} -> 16426.24 | E20: =C20-D20 -> 0 | F20: =IF(D20=0,"Missing in bank",IF(ABS(E20)<0.001,"Exact",IF(ABS(E20)<=0.1,"Tolerance","Exception"))) -> Exact
A21: RCPT-0020 | B21: 46192 | C21: 11094.78 | D21: {=IFERROR(_xlfn.XLOOKUP(A21,Bank!$A:$A,Bank!$C:$C),0)} -> 11094.78 | E21: =C21-D21 -> 0 | F21: =IF(D21=0,"Missing in bank",IF(ABS(E21)<0.001,"Exact",IF(ABS(E21)<=0.1,"Tolerance","Exception"))) -> Exact
A22: RCPT-0021 | B22: 46198 | C22: 12126.64 | D22: {=IFERROR(_xlfn.XLOOKUP(A22,Bank!$A:$A,Bank!$C:$C),0)} -> 12126.64 | E22: =C22-D22 -> 0 | F22: =IF(D22=0,"Missing in bank",IF(ABS(E22)<0.001,"Exact",IF(ABS(E22)<=0.1,"Tolerance","Exception"))) -> Exact
A23: RCPT-0022 | B23: 46184 | C23: 1912.22 | D23: {=IFERROR(_xlfn.XLOOKUP(A23,Bank!$A:$A,Bank!$C:$C),0)} -> 1912.22 | E23: =C23-D23 -> 0 | F23: =IF(D23=0,"Missing in bank",IF(ABS(E23)<0.001,"Exact",IF(ABS(E23)<=0.1,"Tolerance","Exception"))) -> Exact
A24: RCPT-0023 | B24: 46181 | C24: 14066.36 | D24: {=IFERROR(_xlfn.XLOOKUP(A24,Bank!$A:$A,Bank!$C:$C),0)} -> 0 | E24: =C24-D24 -> 14066.36 | F24: =IF(D24=0,"Missing in bank",IF(ABS(E24)<0.001,"Exact",IF(ABS(E24)<=0.1,"Tolerance","Exception"))) -> Missing in bank | G24: AR Analyst
A25: RCPT-0024 | B25: 46189 | C25: 7785.97 | D25: {=IFERROR(_xlfn.XLOOKUP(A25,Bank!$A:$A,Bank!$C:$C),0)} -> 7785.97 | E25: =C25-D25 -> 0 | F25: =IF(D25=0,"Missing in bank",IF(ABS(E25)<0.001,"Exact",IF(ABS(E25)<=0.1,"Tolerance","Exception"))) -> Exact
A26: RCPT-0025 | B26: 46203 | C26: 16369.22 | D26: {=IFERROR(_xlfn.XLOOKUP(A26,Bank!$A:$A,Bank!$C:$C),0)} -> 16369.22 | E26: =C26-D26 -> 0 | F26: =IF(D26=0,"Missing in bank",IF(ABS(E26)<0.001,"Exact",IF(ABS(E26)<=0.1,"Tolerance","Exception"))) -> Exact
A27: RCPT-0026 | B27: 46174 | C27: 4917.93 | D27: {=IFERROR(_xlfn.XLOOKUP(A27,Bank!$A:$A,Bank!$C:$C),0)} -> 4917.93 | E27: =C27-D27 -> 0 | F27: =IF(D27=0,"Missing in bank",IF(ABS(E27)<0.001,"Exact",IF(ABS(E27)<=0.1,"Tolerance","Exception"))) -> Exact
A28: RCPT-0027 | B28: 46183 | C28: 6465.65 | D28: {=IFERROR(_xlfn.XLOOKUP(A28,Bank!$A:$A,Bank!$C:$C),0)} -> 6465.65 | E28: =C28-D28 -> 0 | F28: =IF(D28=0,"Missing in bank",IF(ABS(E28)<0.001,"Exact",IF(ABS(E28)<=0.1,"Tolerance","Exception"))) -> Exact
A29: RCPT-0028 | B29: 46195 | C29: 1319.33 | D29: {=IFERROR(_xlfn.XLOOKUP(A29,Bank!$A:$A,Bank!$C:$C),0)} -> 1319.33 | E29: =C29-D29 -> 0 | F29: =IF(D29=0,"Missing in bank",IF(ABS(E29)<0.001,"Exact",IF(ABS(E29)<=0.1,"Tolerance","Exception"))) -> Exact
A30: RCPT-0029 | B30: 46187 | C30: 9931.04 | D30: {=IFERROR(_xlfn.XLOOKUP(A30,Bank!$A:$A,Bank!$C:$C),0)} -> 9931.04 | E30: =C30-D30 -> 0 | F30: =IF(D30=0,"Missing in bank",IF(ABS(E30)<0.001,"Exact",IF(ABS(E30)<=0.1,"Tolerance","Exception"))) -> Exact
A31: RCPT-0030 | B31: 46177 | C31: 18429.25 | D31: {=IFERROR(_xlfn.XLOOKUP(A31,Bank!$A:$A,Bank!$C:$C),0)} -> 18429.25 | E31: =C31-D31 -> 0 | F31: =IF(D31=0,"Missing in bank",IF(ABS(E31)<0.001,"Exact",IF(ABS(E31)<=0.1,"Tolerance","Exception"))) -> Exact
A32: RCPT-0031 | B32: 46191 | C32: 19622.89 | D32: {=IFERROR(_xlfn.XLOOKUP(A32,Bank!$A:$A,Bank!$C:$C),0)} -> 19622.89 | E32: =C32-D32 -> 0 | F32: =IF(D32=0,"Missing in bank",IF(ABS(E32)<0.001,"Exact",IF(ABS(E32)<=0.1,"Tolerance","Exception"))) -> Exact
A33: RCPT-0032 | B33: 46178 | C33: 21396.69 | D33: {=IFERROR(_xlfn.XLOOKUP(A33,Bank!$A:$A,Bank!$C:$C),0)} -> 21396.69 | E33: =C33-D33 -> 0 | F33: =IF(D33=0,"Missing in bank",IF(ABS(E33)<0.001,"Exact",IF(ABS(E33)<=0.1,"Tolerance","Exception"))) -> Exact
A34: RCPT-0033 | B34: 46174 | C34: 16098.8 | D34: {=IFERROR(_xlfn.XLOOKUP(A34,Bank!$A:$A,Bank!$C:$C),0)} -> 16098.8 | E34: =C34-D34 -> 0 | F34: =IF(D34=0,"Missing in bank",IF(ABS(E34)<0.001,"Exact",IF(ABS(E34)<=0.1,"Tolerance","Exception"))) -> Exact
A35: RCPT-0034 | B35: 46180 | C35: 11901.93 | D35: {=IFERROR(_xlfn.XLOOKUP(A35,Bank!$A:$A,Bank!$C:$C),0)} -> 11901.93 | E35: =C35-D35 -> 0 | F35: =IF(D35=0,"Missing in bank",IF(ABS(E35)<0.001,"Exact",IF(ABS(E35)<=0.1,"Tolerance","Exception"))) -> Exact
A36: RCPT-0035 | B36: 46195 | C36: 16498.73 | D36: {=IFERROR(_xlfn.XLOOKUP(A36,Bank!$A:$A,Bank!$C:$C),0)} -> 16498.73 | E36: =C36-D36 -> 0 | F36: =IF(D36=0,"Missing in bank",IF(ABS(E36)<0.001,"Exact",IF(ABS(E36)<=0.1,"Tolerance","Exception"))) -> Exact
... A45: RCPT-0044 | B45: 46193 | C45: 17655.46 | D45: {=IFERROR(_xlfn.XLOOKUP(A45,Bank!$A:$A,Bank!$C:$C),0)} -> 17655.46 | E45: =C45-D45 -> 0 | F45: =IF(D45=0,"Missing in bank",IF(ABS(E45)<0.001,"Exact",IF(ABS(E45)<=0.1,"Tolerance","Exception"))) -> Exact
A46: RCPT-0045 | B46: 46187 | C46: 17110.44 | D46: {=IFERROR(_xlfn.XLOOKUP(A46,Bank!$A:$A,Bank!$C:$C),0)} -> 17110.49 | E46: =C46-D46 -> -0.05 | F46: =IF(D46=0,"Missing in bank",IF(ABS(E46)<0.001,"Exact",IF(ABS(E46)<=0.1,"Tolerance","Exception"))) -> Tolerance | G46: AR Analyst
A47: RCPT-0046 | B47: 46188 | C47: 15389.79 | D47: {=IFERROR(_xlfn.XLOOKUP(A47,Bank!$A:$A,Bank!$C:$C),0)} -> 15389.79 | E47: =C47-D47 -> 0 | F47: =IF(D47=0,"Missing in bank",IF(ABS(E47)<0.001,"Exact",IF(ABS(E47)<=0.1,"Tolerance","Exception"))) -> Exact
A48: RCPT-0047 | B48: 46175 | C48: 10561.79 | D48: {=IFERROR(_xlfn.XLOOKUP(A48,Bank!$A:$A,Bank!$C:$C),0)} -> 10561.79 | E48: =C48-D48 -> 0 | F48: =IF(D48=0,"Missing in bank",IF(ABS(E48)<0.001,"Exact",IF(ABS(E48)<=0.1,"Tolerance","Exception"))) -> Exact
...

Sheet Summary
A1: Reconciliation summary
A3: Measure | B3: Calculated | C3: Expected
A4: Ledger total | B4: =SUM(Ledger!C:C) -> 1046392.7 | C4: 1046392.7
A5: Bank total | B5: =SUM(Bank!C:C) -> 1005273.8 | C5: 1005273.8
A6: Exact matches | B6: =COUNTIF(Reconciliation!F:F,"Exact") -> 84 | C6: 84
A7: Tolerance matches | B7: =COUNTIF(Reconciliation!F:F,"Tolerance") -> 2 | C7: 2
A8: Unresolved exceptions | B8: =COUNTIF(Reconciliation!F:F,"Exception")+COUNTIF(Reconciliation!F:F,"Missing in bank") -> 6 | C8: 6

Sheet Variance Data
A1: Month | B1: Month No | C1: Department | D1: Actual | E1: Budget | F1: Variance | G1: Variance %
A2: Jan | B2: 1 | C2: Retail | D2: 684667 | E2: 681656 | F2: 3011 | G2: 0.004417184
A3: Jan | B3: 1 | C3: SME | D3: 600040 | E3: 617856 | F3: -17816 | G3: -0.028835198
A4: Jan | B4: 1 | C4: Enterprise | D4: 383412 | E4: 431900 | F4: -48488 | G4: -0.11226673
A5: Jan | B5: 1 | C5: Digital | D5: 467836 | E5: 417933 | F5: 49903 | G5: 0.11940431
A6: Feb | B6: 2 | C6: Retail | D6: 600151 | E6: 541849 | F6: 58302 | G6: 0.10759824
A7: Feb | B7: 2 | C7: SME | D7: 642451 | E7: 590987 | F7: 51464 | G7: 0.087081442
A8: Feb | B8: 2 | C8: Enterprise | D8: 434773 | E8: 421956 | F8: 12817 | G8: 0.030375205
A9: Feb | B9: 2 | C9: Digital | D9: 700845 | E9: 671851 | F9: 28994 | G9: 0.043155402
A10: Mar | B10: 3 | C10: Retail | D10: 515151 | E10: 517012 | F10: -1861 | G10: -0.0035995296
A11: Mar | B11: 3 | C11: SME | D11: 528055 | E11: 464268 | F11: 63787 | G11: 0.13739263
A12: Mar | B12: 3 | C12: Enterprise | D12: 454035 | E12: 443604 | F12: 10431 | G12: 0.023514215
A13: Mar | B13: 3 | C13: Digital | D13: 586881 | E13: 592847 | F13: -5966 | G13: -0.010063305
... A25: Jun | B25: 6 | C25: Digital | D25: 517232 | E25: 549493 | F25: -32261 | G25: -0.058710484
